[2024-03-18T20:25:11.957+0000] {taskinstance.py:1979} INFO - Dependencies all met for dep_context=non-requeueable deps ti=<TaskInstance: my_dag.Options_Crawler manual__2024-03-18T20:25:09.762791+00:00 [queued]>
[2024-03-18T20:25:11.963+0000] {taskinstance.py:1979} INFO - Dependencies all met for dep_context=requeueable deps ti=<TaskInstance: my_dag.Options_Crawler manual__2024-03-18T20:25:09.762791+00:00 [queued]>
[2024-03-18T20:25:11.964+0000] {taskinstance.py:2193} INFO - Starting attempt 1 of 1
[2024-03-18T20:25:11.972+0000] {taskinstance.py:2217} INFO - Executing <Task(PythonOperator): Options_Crawler> on 2024-03-18 20:25:09.762791+00:00
[2024-03-18T20:25:11.977+0000] {standard_task_runner.py:60} INFO - Started process 141 to run task
[2024-03-18T20:25:11.980+0000] {standard_task_runner.py:87} INFO - Running: ['***', 'tasks', 'run', 'my_dag', 'Options_Crawler', 'manual__2024-03-18T20:25:09.762791+00:00', '--job-id', '46', '--raw', '--subdir', 'DAGS_FOLDER/crawler.py', '--cfg-path', '/tmp/tmpjh7nrvf9']
[2024-03-18T20:25:11.982+0000] {standard_task_runner.py:88} INFO - Job 46: Subtask Options_Crawler
[2024-03-18T20:25:12.018+0000] {task_command.py:423} INFO - Running <TaskInstance: my_dag.Options_Crawler manual__2024-03-18T20:25:09.762791+00:00 [running]> on host 65bb8df62808
[2024-03-18T20:25:12.085+0000] {taskinstance.py:2513} INFO - Exporting env vars: AIRFLOW_CTX_DAG_OWNER='***' AIRFLOW_CTX_DAG_ID='my_dag' AIRFLOW_CTX_TASK_ID='Options_Crawler' AIRFLOW_CTX_EXECUTION_DATE='2024-03-18T20:25:09.762791+00:00' AIRFLOW_CTX_TRY_NUMBER='1' AIRFLOW_CTX_DAG_RUN_ID='manual__2024-03-18T20:25:09.762791+00:00'
[2024-03-18T20:25:45.093+0000] {logging_mixin.py:188} INFO - ~~~~~~~~~~~~~~~~~~~~~~~~~~~~~~~~~~~~~~~~ 
[2024-03-18T20:25:45.094+0000] {logging_mixin.py:188} INFO -  the error acuire in crawl data from TSETMS localhost:27017: [Errno 111] Connection refused (configured timeouts: socketTimeoutMS: 20000.0ms, connectTimeoutMS: 20000.0ms), Timeout: 30s, Topology Description: <TopologyDescription id: 65f8a32aacf4644a45990f35, topology_type: Unknown, servers: [<ServerDescription ('localhost', 27017) server_type: Unknown, rtt: None, error=AutoReconnect('localhost:27017: [Errno 111] Connection refused (configured timeouts: socketTimeoutMS: 20000.0ms, connectTimeoutMS: 20000.0ms)')>]>
[2024-03-18T20:25:45.098+0000] {python.py:202} INFO - Done. Returned value was: None
[2024-03-18T20:25:45.107+0000] {taskinstance.py:1149} INFO - Marking task as SUCCESS. dag_id=my_dag, task_id=Options_Crawler, execution_date=20240318T202509, start_date=20240318T202511, end_date=20240318T202545
[2024-03-18T20:25:45.157+0000] {local_task_job_runner.py:234} INFO - Task exited with return code 0
[2024-03-18T20:25:45.173+0000] {taskinstance.py:3312} INFO - 0 downstream tasks scheduled from follow-on schedule check
