[2024-03-19T10:57:01.586+0000] {taskinstance.py:1979} INFO - Dependencies all met for dep_context=non-requeueable deps ti=<TaskInstance: Crawler.your_task_id scheduled__2024-03-19T10:56:00+00:00 [queued]>
[2024-03-19T10:57:01.593+0000] {taskinstance.py:1979} INFO - Dependencies all met for dep_context=requeueable deps ti=<TaskInstance: Crawler.your_task_id scheduled__2024-03-19T10:56:00+00:00 [queued]>
[2024-03-19T10:57:01.594+0000] {taskinstance.py:2193} INFO - Starting attempt 1 of 1
[2024-03-19T10:57:01.606+0000] {taskinstance.py:2217} INFO - Executing <Task(PythonOperator): your_task_id> on 2024-03-19 10:56:00+00:00
[2024-03-19T10:57:01.612+0000] {standard_task_runner.py:60} INFO - Started process 1746 to run task
[2024-03-19T10:57:01.615+0000] {standard_task_runner.py:87} INFO - Running: ['***', 'tasks', 'run', 'Crawler', 'your_task_id', 'scheduled__2024-03-19T10:56:00+00:00', '--job-id', '174', '--raw', '--subdir', 'DAGS_FOLDER/new_crawler.py', '--cfg-path', '/tmp/tmpl8f5ieg0']
[2024-03-19T10:57:01.618+0000] {standard_task_runner.py:88} INFO - Job 174: Subtask your_task_id
[2024-03-19T10:57:01.664+0000] {task_command.py:423} INFO - Running <TaskInstance: Crawler.your_task_id scheduled__2024-03-19T10:56:00+00:00 [running]> on host d99d270e5c22
[2024-03-19T10:57:01.736+0000] {taskinstance.py:2513} INFO - Exporting env vars: AIRFLOW_CTX_DAG_OWNER='Xirano' AIRFLOW_CTX_DAG_ID='Crawler' AIRFLOW_CTX_TASK_ID='your_task_id' AIRFLOW_CTX_EXECUTION_DATE='2024-03-19T10:56:00+00:00' AIRFLOW_CTX_TRY_NUMBER='1' AIRFLOW_CTX_DAG_RUN_ID='scheduled__2024-03-19T10:56:00+00:00'
[2024-03-19T10:57:01.769+0000] {logging_mixin.py:188} INFO - ~~~~~~~~~~~~~~~~~~~~~~~~~~~~~~~~~~~~~~~~ 
[2024-03-19T10:57:01.770+0000] {logging_mixin.py:188} INFO -  the error acuire in crawl data from TSETMS HTTPSConnectionPool(host='cdn.tsetmc.com', port=443): Max retries exceeded with url: /api/Instrument/GetInstrumentOptionMarketWatch/1 (Caused by NewConnectionError('<urllib3.connection.HTTPSConnection object at 0x7f51c2d29af0>: Failed to establish a new connection: [Errno -2] Name or service not known'))
[2024-03-19T10:57:01.770+0000] {python.py:202} INFO - Done. Returned value was: None
[2024-03-19T10:57:01.780+0000] {taskinstance.py:1149} INFO - Marking task as SUCCESS. dag_id=Crawler, task_id=your_task_id, execution_date=20240319T105600, start_date=20240319T105701, end_date=20240319T105701
[2024-03-19T10:57:01.835+0000] {local_task_job_runner.py:234} INFO - Task exited with return code 0
[2024-03-19T10:57:01.850+0000] {taskinstance.py:3312} INFO - 0 downstream tasks scheduled from follow-on schedule check
