[2024-03-19T11:35:27.524+0000] {taskinstance.py:1979} INFO - Dependencies all met for dep_context=non-requeueable deps ti=<TaskInstance: Crawler.your_task_id scheduled__2024-03-19T11:27:00+00:00 [queued]>
[2024-03-19T11:35:27.532+0000] {taskinstance.py:1979} INFO - Dependencies all met for dep_context=requeueable deps ti=<TaskInstance: Crawler.your_task_id scheduled__2024-03-19T11:27:00+00:00 [queued]>
[2024-03-19T11:35:27.532+0000] {taskinstance.py:2193} INFO - Starting attempt 1 of 1
[2024-03-19T11:35:27.542+0000] {taskinstance.py:2217} INFO - Executing <Task(PythonOperator): your_task_id> on 2024-03-19 11:27:00+00:00
[2024-03-19T11:35:27.550+0000] {standard_task_runner.py:60} INFO - Started process 271 to run task
[2024-03-19T11:35:27.553+0000] {standard_task_runner.py:87} INFO - Running: ['***', 'tasks', 'run', 'Crawler', 'your_task_id', 'scheduled__2024-03-19T11:27:00+00:00', '--job-id', '207', '--raw', '--subdir', 'DAGS_FOLDER/new_crawler.py', '--cfg-path', '/tmp/tmpu8ozzrby']
[2024-03-19T11:35:27.555+0000] {standard_task_runner.py:88} INFO - Job 207: Subtask your_task_id
[2024-03-19T11:35:27.598+0000] {task_command.py:423} INFO - Running <TaskInstance: Crawler.your_task_id scheduled__2024-03-19T11:27:00+00:00 [running]> on host 26a0b219297f
[2024-03-19T11:35:27.670+0000] {taskinstance.py:2513} INFO - Exporting env vars: AIRFLOW_CTX_DAG_OWNER='Xirano' AIRFLOW_CTX_DAG_ID='Crawler' AIRFLOW_CTX_TASK_ID='your_task_id' AIRFLOW_CTX_EXECUTION_DATE='2024-03-19T11:27:00+00:00' AIRFLOW_CTX_TRY_NUMBER='1' AIRFLOW_CTX_DAG_RUN_ID='scheduled__2024-03-19T11:27:00+00:00'
[2024-03-19T11:35:27.678+0000] {logging_mixin.py:188} INFO - ~~~~~~~~~~~~~~~~~~~~~~~~~~~~~~~~~~~~~~~~ 
[2024-03-19T11:35:27.678+0000] {logging_mixin.py:188} INFO -  the error acuire in crawl data from TSETMS HTTPSConnectionPool(host='cdn.tsetmc.com', port=443): Max retries exceeded with url: /api/Instrument/GetInstrumentOptionMarketWatch/1 (Caused by NewConnectionError('<urllib3.connection.HTTPSConnection object at 0x7fc18ff9ea30>: Failed to establish a new connection: [Errno -3] Temporary failure in name resolution'))
[2024-03-19T11:35:27.678+0000] {python.py:202} INFO - Done. Returned value was: None
[2024-03-19T11:35:27.688+0000] {taskinstance.py:1149} INFO - Marking task as SUCCESS. dag_id=Crawler, task_id=your_task_id, execution_date=20240319T112700, start_date=20240319T113527, end_date=20240319T113527
[2024-03-19T11:35:27.732+0000] {local_task_job_runner.py:234} INFO - Task exited with return code 0
[2024-03-19T11:35:28.538+0000] {taskinstance.py:3312} INFO - 0 downstream tasks scheduled from follow-on schedule check
