[2024-03-17T10:19:32.196+0000] {taskinstance.py:1979} INFO - Dependencies all met for dep_context=non-requeueable deps ti=<TaskInstance: my_dag.Options_Crawler manual__2024-03-17T10:19:30.306404+00:00 [queued]>
[2024-03-17T10:19:32.202+0000] {taskinstance.py:1979} INFO - Dependencies all met for dep_context=requeueable deps ti=<TaskInstance: my_dag.Options_Crawler manual__2024-03-17T10:19:30.306404+00:00 [queued]>
[2024-03-17T10:19:32.203+0000] {taskinstance.py:2193} INFO - Starting attempt 1 of 1
[2024-03-17T10:19:32.211+0000] {taskinstance.py:2217} INFO - Executing <Task(PythonOperator): Options_Crawler> on 2024-03-17 10:19:30.306404+00:00
[2024-03-17T10:19:32.215+0000] {standard_task_runner.py:60} INFO - Started process 69 to run task
[2024-03-17T10:19:32.218+0000] {standard_task_runner.py:87} INFO - Running: ['***', 'tasks', 'run', 'my_dag', 'Options_Crawler', 'manual__2024-03-17T10:19:30.306404+00:00', '--job-id', '24', '--raw', '--subdir', 'DAGS_FOLDER/crawler.py', '--cfg-path', '/tmp/tmp42d4zcfy']
[2024-03-17T10:19:32.221+0000] {standard_task_runner.py:88} INFO - Job 24: Subtask Options_Crawler
[2024-03-17T10:19:32.261+0000] {task_command.py:423} INFO - Running <TaskInstance: my_dag.Options_Crawler manual__2024-03-17T10:19:30.306404+00:00 [running]> on host d46fa25f426c
[2024-03-17T10:19:32.317+0000] {taskinstance.py:2513} INFO - Exporting env vars: AIRFLOW_CTX_DAG_OWNER='***' AIRFLOW_CTX_DAG_ID='my_dag' AIRFLOW_CTX_TASK_ID='Options_Crawler' AIRFLOW_CTX_EXECUTION_DATE='2024-03-17T10:19:30.306404+00:00' AIRFLOW_CTX_TRY_NUMBER='1' AIRFLOW_CTX_DAG_RUN_ID='manual__2024-03-17T10:19:30.306404+00:00'
[2024-03-17T10:20:06.003+0000] {logging_mixin.py:188} INFO - ~~~~~~~~~~~~~~~~~~~~~~~~~~~~~~~~~~~~~~~~ 
[2024-03-17T10:20:06.004+0000] {logging_mixin.py:188} INFO -  the error acuire in crawl data from TSETMS localhost:27017: [Errno 111] Connection refused (configured timeouts: socketTimeoutMS: 20000.0ms, connectTimeoutMS: 20000.0ms), Timeout: 30s, Topology Description: <TopologyDescription id: 65f6c3b776bae7bd9e22d570, topology_type: Unknown, servers: [<ServerDescription ('localhost', 27017) server_type: Unknown, rtt: None, error=AutoReconnect('localhost:27017: [Errno 111] Connection refused (configured timeouts: socketTimeoutMS: 20000.0ms, connectTimeoutMS: 20000.0ms)')>]>
[2024-03-17T10:20:06.006+0000] {python.py:202} INFO - Done. Returned value was: None
[2024-03-17T10:20:06.014+0000] {taskinstance.py:1149} INFO - Marking task as SUCCESS. dag_id=my_dag, task_id=Options_Crawler, execution_date=20240317T101930, start_date=20240317T101932, end_date=20240317T102006
[2024-03-17T10:20:06.050+0000] {local_task_job_runner.py:234} INFO - Task exited with return code 0
[2024-03-17T10:20:06.063+0000] {taskinstance.py:3312} INFO - 0 downstream tasks scheduled from follow-on schedule check
