[2024-03-19T11:35:31.873+0000] {taskinstance.py:1979} INFO - Dependencies all met for dep_context=non-requeueable deps ti=<TaskInstance: Crawler.your_task_id scheduled__2024-03-19T11:31:00+00:00 [queued]>
[2024-03-19T11:35:31.879+0000] {taskinstance.py:1979} INFO - Dependencies all met for dep_context=requeueable deps ti=<TaskInstance: Crawler.your_task_id scheduled__2024-03-19T11:31:00+00:00 [queued]>
[2024-03-19T11:35:31.879+0000] {taskinstance.py:2193} INFO - Starting attempt 1 of 1
[2024-03-19T11:35:31.888+0000] {taskinstance.py:2217} INFO - Executing <Task(PythonOperator): your_task_id> on 2024-03-19 11:31:00+00:00
[2024-03-19T11:35:31.893+0000] {standard_task_runner.py:60} INFO - Started process 282 to run task
[2024-03-19T11:35:31.896+0000] {standard_task_runner.py:87} INFO - Running: ['***', 'tasks', 'run', 'Crawler', 'your_task_id', 'scheduled__2024-03-19T11:31:00+00:00', '--job-id', '210', '--raw', '--subdir', 'DAGS_FOLDER/new_crawler.py', '--cfg-path', '/tmp/tmp_1extah_']
[2024-03-19T11:35:31.899+0000] {standard_task_runner.py:88} INFO - Job 210: Subtask your_task_id
[2024-03-19T11:35:31.938+0000] {task_command.py:423} INFO - Running <TaskInstance: Crawler.your_task_id scheduled__2024-03-19T11:31:00+00:00 [running]> on host 26a0b219297f
[2024-03-19T11:35:32.003+0000] {taskinstance.py:2513} INFO - Exporting env vars: AIRFLOW_CTX_DAG_OWNER='Xirano' AIRFLOW_CTX_DAG_ID='Crawler' AIRFLOW_CTX_TASK_ID='your_task_id' AIRFLOW_CTX_EXECUTION_DATE='2024-03-19T11:31:00+00:00' AIRFLOW_CTX_TRY_NUMBER='1' AIRFLOW_CTX_DAG_RUN_ID='scheduled__2024-03-19T11:31:00+00:00'
[2024-03-19T11:35:32.008+0000] {logging_mixin.py:188} INFO - ~~~~~~~~~~~~~~~~~~~~~~~~~~~~~~~~~~~~~~~~ 
[2024-03-19T11:35:32.009+0000] {logging_mixin.py:188} INFO -  the error acuire in crawl data from TSETMS HTTPSConnectionPool(host='cdn.tsetmc.com', port=443): Max retries exceeded with url: /api/Instrument/GetInstrumentOptionMarketWatch/1 (Caused by NewConnectionError('<urllib3.connection.HTTPSConnection object at 0x7fc18ffa97f0>: Failed to establish a new connection: [Errno -3] Temporary failure in name resolution'))
[2024-03-19T11:35:32.009+0000] {python.py:202} INFO - Done. Returned value was: None
[2024-03-19T11:35:32.018+0000] {taskinstance.py:1149} INFO - Marking task as SUCCESS. dag_id=Crawler, task_id=your_task_id, execution_date=20240319T113100, start_date=20240319T113531, end_date=20240319T113532
[2024-03-19T11:35:32.035+0000] {local_task_job_runner.py:234} INFO - Task exited with return code 0
[2024-03-19T11:35:32.050+0000] {taskinstance.py:3312} INFO - 0 downstream tasks scheduled from follow-on schedule check
