[2024-03-19T09:52:57.201+0000] {taskinstance.py:1979} INFO - Dependencies all met for dep_context=non-requeueable deps ti=<TaskInstance: Crawler.your_task_id scheduled__2024-03-18T16:00:00+00:00 [queued]>
[2024-03-19T09:52:57.210+0000] {taskinstance.py:1979} INFO - Dependencies all met for dep_context=requeueable deps ti=<TaskInstance: Crawler.your_task_id scheduled__2024-03-18T16:00:00+00:00 [queued]>
[2024-03-19T09:52:57.210+0000] {taskinstance.py:2193} INFO - Starting attempt 1 of 1
[2024-03-19T09:52:57.222+0000] {taskinstance.py:2217} INFO - Executing <Task(PythonOperator): your_task_id> on 2024-03-18 16:00:00+00:00
[2024-03-19T09:52:57.229+0000] {standard_task_runner.py:60} INFO - Started process 563 to run task
[2024-03-19T09:52:57.233+0000] {standard_task_runner.py:87} INFO - Running: ['***', 'tasks', 'run', 'Crawler', 'your_task_id', 'scheduled__2024-03-18T16:00:00+00:00', '--job-id', '104', '--raw', '--subdir', 'DAGS_FOLDER/new_crawler.py', '--cfg-path', '/tmp/tmpw7c01oxw']
[2024-03-19T09:52:57.237+0000] {standard_task_runner.py:88} INFO - Job 104: Subtask your_task_id
[2024-03-19T09:52:57.315+0000] {task_command.py:423} INFO - Running <TaskInstance: Crawler.your_task_id scheduled__2024-03-18T16:00:00+00:00 [running]> on host d99d270e5c22
[2024-03-19T09:52:57.410+0000] {taskinstance.py:2513} INFO - Exporting env vars: AIRFLOW_CTX_DAG_OWNER='Xirano' AIRFLOW_CTX_DAG_ID='Crawler' AIRFLOW_CTX_TASK_ID='your_task_id' AIRFLOW_CTX_EXECUTION_DATE='2024-03-18T16:00:00+00:00' AIRFLOW_CTX_TRY_NUMBER='1' AIRFLOW_CTX_DAG_RUN_ID='scheduled__2024-03-18T16:00:00+00:00'
[2024-03-19T09:53:05.405+0000] {logging_mixin.py:188} INFO - ~~~~~~~~~~~~~~~~~~~~~~~~~~~~~~~~~~~~~~~~ 
[2024-03-19T09:53:05.438+0000] {logging_mixin.py:188} INFO -  the error acuire in crawl data from TSETMS HTTPSConnectionPool(host='cdn.tsetmc.com', port=443): Max retries exceeded with url: /api/Instrument/GetInstrumentOptionMarketWatch/1 (Caused by NewConnectionError('<urllib3.connection.HTTPSConnection object at 0x7f51c2d0b700>: Failed to establish a new connection: [Errno -3] Temporary failure in name resolution'))
[2024-03-19T09:53:05.446+0000] {python.py:202} INFO - Done. Returned value was: None
[2024-03-19T09:53:17.037+0000] {local_task_job_runner.py:234} INFO - Task exited with return code -9
[2024-03-19T09:53:17.117+0000] {taskinstance.py:3312} INFO - 0 downstream tasks scheduled from follow-on schedule check
