[2024-03-17T10:05:20.146+0000] {taskinstance.py:1979} INFO - Dependencies all met for dep_context=non-requeueable deps ti=<TaskInstance: my_dag.training_model manual__2024-03-17T10:05:18.339649+00:00 [queued]>
[2024-03-17T10:05:20.152+0000] {taskinstance.py:1979} INFO - Dependencies all met for dep_context=requeueable deps ti=<TaskInstance: my_dag.training_model manual__2024-03-17T10:05:18.339649+00:00 [queued]>
[2024-03-17T10:05:20.153+0000] {taskinstance.py:2193} INFO - Starting attempt 1 of 1
[2024-03-17T10:05:20.162+0000] {taskinstance.py:2217} INFO - Executing <Task(PythonOperator): training_model> on 2024-03-17 10:05:18.339649+00:00
[2024-03-17T10:05:20.167+0000] {standard_task_runner.py:60} INFO - Started process 87 to run task
[2024-03-17T10:05:20.170+0000] {standard_task_runner.py:87} INFO - Running: ['***', 'tasks', 'run', 'my_dag', 'training_model', 'manual__2024-03-17T10:05:18.339649+00:00', '--job-id', '18', '--raw', '--subdir', 'DAGS_FOLDER/crawler.py', '--cfg-path', '/tmp/tmpo0zfz2wl']
[2024-03-17T10:05:20.172+0000] {standard_task_runner.py:88} INFO - Job 18: Subtask training_model
[2024-03-17T10:05:20.210+0000] {task_command.py:423} INFO - Running <TaskInstance: my_dag.training_model manual__2024-03-17T10:05:18.339649+00:00 [running]> on host d46fa25f426c
[2024-03-17T10:05:20.272+0000] {taskinstance.py:2513} INFO - Exporting env vars: AIRFLOW_CTX_DAG_OWNER='***' AIRFLOW_CTX_DAG_ID='my_dag' AIRFLOW_CTX_TASK_ID='training_model' AIRFLOW_CTX_EXECUTION_DATE='2024-03-17T10:05:18.339649+00:00' AIRFLOW_CTX_TRY_NUMBER='1' AIRFLOW_CTX_DAG_RUN_ID='manual__2024-03-17T10:05:18.339649+00:00'
[2024-03-17T10:05:52.754+0000] {taskinstance.py:2731} ERROR - Task failed with exception
Traceback (most recent call last):
  File "/home/airflow/.local/lib/python3.8/site-packages/airflow/models/taskinstance.py", line 444, in _execute_task
    result = _execute_callable(context=context, **execute_callable_kwargs)
  File "/home/airflow/.local/lib/python3.8/site-packages/airflow/models/taskinstance.py", line 414, in _execute_callable
    return execute_callable(context=context, **execute_callable_kwargs)
  File "/home/airflow/.local/lib/python3.8/site-packages/airflow/operators/python.py", line 200, in execute
    return_value = self.execute_callable()
  File "/home/airflow/.local/lib/python3.8/site-packages/airflow/operators/python.py", line 217, in execute_callable
    return self.python_callable(*self.op_args, **self.op_kwargs)
  File "/opt/airflow/dags/crawler.py", line 43, in scrape_and_store
    result =collection.insert_many(data_to_store)
  File "/home/airflow/.local/lib/python3.8/site-packages/pymongo/_csot.py", line 107, in csot_wrapper
    return func(self, *args, **kwargs)
  File "/home/airflow/.local/lib/python3.8/site-packages/pymongo/collection.py", line 755, in insert_many
    blk.execute(write_concern, session=session)
  File "/home/airflow/.local/lib/python3.8/site-packages/pymongo/bulk.py", line 576, in execute
    return self.execute_command(generator, write_concern, session)
  File "/home/airflow/.local/lib/python3.8/site-packages/pymongo/bulk.py", line 443, in execute_command
    client._retryable_write(self.is_retryable, retryable_bulk, session, bulk=self)
  File "/home/airflow/.local/lib/python3.8/site-packages/pymongo/mongo_client.py", line 1522, in _retryable_write
    with self._tmp_session(session) as s:
  File "/usr/local/lib/python3.8/contextlib.py", line 113, in __enter__
    return next(self.gen)
  File "/home/airflow/.local/lib/python3.8/site-packages/pymongo/mongo_client.py", line 1840, in _tmp_session
    s = self._ensure_session(session)
  File "/home/airflow/.local/lib/python3.8/site-packages/pymongo/mongo_client.py", line 1823, in _ensure_session
    return self.__start_session(True, causal_consistency=False)
  File "/home/airflow/.local/lib/python3.8/site-packages/pymongo/mongo_client.py", line 1766, in __start_session
    self._topology._check_implicit_session_support()
  File "/home/airflow/.local/lib/python3.8/site-packages/pymongo/topology.py", line 573, in _check_implicit_session_support
    self._check_session_support()
  File "/home/airflow/.local/lib/python3.8/site-packages/pymongo/topology.py", line 589, in _check_session_support
    self._select_servers_loop(
  File "/home/airflow/.local/lib/python3.8/site-packages/pymongo/topology.py", line 259, in _select_servers_loop
    raise ServerSelectionTimeoutError(
pymongo.errors.ServerSelectionTimeoutError: localhost:27017: [Errno 111] Connection refused (configured timeouts: socketTimeoutMS: 20000.0ms, connectTimeoutMS: 20000.0ms), Timeout: 30s, Topology Description: <TopologyDescription id: 65f6c06216d54681c5887f45, topology_type: Unknown, servers: [<ServerDescription ('localhost', 27017) server_type: Unknown, rtt: None, error=AutoReconnect('localhost:27017: [Errno 111] Connection refused (configured timeouts: socketTimeoutMS: 20000.0ms, connectTimeoutMS: 20000.0ms)')>]>
[2024-03-17T10:05:52.767+0000] {taskinstance.py:1149} INFO - Marking task as FAILED. dag_id=my_dag, task_id=training_model, execution_date=20240317T100518, start_date=20240317T100520, end_date=20240317T100552
[2024-03-17T10:05:52.782+0000] {standard_task_runner.py:107} ERROR - Failed to execute job 18 for task training_model (localhost:27017: [Errno 111] Connection refused (configured timeouts: socketTimeoutMS: 20000.0ms, connectTimeoutMS: 20000.0ms), Timeout: 30s, Topology Description: <TopologyDescription id: 65f6c06216d54681c5887f45, topology_type: Unknown, servers: [<ServerDescription ('localhost', 27017) server_type: Unknown, rtt: None, error=AutoReconnect('localhost:27017: [Errno 111] Connection refused (configured timeouts: socketTimeoutMS: 20000.0ms, connectTimeoutMS: 20000.0ms)')>]>; 87)
[2024-03-17T10:05:52.834+0000] {local_task_job_runner.py:234} INFO - Task exited with return code 1
[2024-03-17T10:05:52.852+0000] {taskinstance.py:3312} INFO - 0 downstream tasks scheduled from follow-on schedule check
