[2024-03-17T10:19:45.259+0000] {taskinstance.py:1979} INFO - Dependencies all met for dep_context=non-requeueable deps ti=<TaskInstance: my_dag.Options_Crawler manual__2024-03-17T10:19:44.122331+00:00 [queued]>
[2024-03-17T10:19:45.265+0000] {taskinstance.py:1979} INFO - Dependencies all met for dep_context=requeueable deps ti=<TaskInstance: my_dag.Options_Crawler manual__2024-03-17T10:19:44.122331+00:00 [queued]>
[2024-03-17T10:19:45.265+0000] {taskinstance.py:2193} INFO - Starting attempt 1 of 1
[2024-03-17T10:19:45.274+0000] {taskinstance.py:2217} INFO - Executing <Task(PythonOperator): Options_Crawler> on 2024-03-17 10:19:44.122331+00:00
[2024-03-17T10:19:45.279+0000] {standard_task_runner.py:60} INFO - Started process 82 to run task
[2024-03-17T10:19:45.282+0000] {standard_task_runner.py:87} INFO - Running: ['***', 'tasks', 'run', 'my_dag', 'Options_Crawler', 'manual__2024-03-17T10:19:44.122331+00:00', '--job-id', '25', '--raw', '--subdir', 'DAGS_FOLDER/crawler.py', '--cfg-path', '/tmp/tmpos1g1is9']
[2024-03-17T10:19:45.284+0000] {standard_task_runner.py:88} INFO - Job 25: Subtask Options_Crawler
[2024-03-17T10:19:45.318+0000] {task_command.py:423} INFO - Running <TaskInstance: my_dag.Options_Crawler manual__2024-03-17T10:19:44.122331+00:00 [running]> on host d46fa25f426c
[2024-03-17T10:19:45.369+0000] {taskinstance.py:2513} INFO - Exporting env vars: AIRFLOW_CTX_DAG_OWNER='***' AIRFLOW_CTX_DAG_ID='my_dag' AIRFLOW_CTX_TASK_ID='Options_Crawler' AIRFLOW_CTX_EXECUTION_DATE='2024-03-17T10:19:44.122331+00:00' AIRFLOW_CTX_TRY_NUMBER='1' AIRFLOW_CTX_DAG_RUN_ID='manual__2024-03-17T10:19:44.122331+00:00'
[2024-03-17T10:20:17.884+0000] {logging_mixin.py:188} INFO - ~~~~~~~~~~~~~~~~~~~~~~~~~~~~~~~~~~~~~~~~ 
[2024-03-17T10:20:17.886+0000] {logging_mixin.py:188} INFO -  the error acuire in crawl data from TSETMS localhost:27017: [Errno 111] Connection refused (configured timeouts: socketTimeoutMS: 20000.0ms, connectTimeoutMS: 20000.0ms), Timeout: 30s, Topology Description: <TopologyDescription id: 65f6c3c3967c48b660d3a841, topology_type: Unknown, servers: [<ServerDescription ('localhost', 27017) server_type: Unknown, rtt: None, error=AutoReconnect('localhost:27017: [Errno 111] Connection refused (configured timeouts: socketTimeoutMS: 20000.0ms, connectTimeoutMS: 20000.0ms)')>]>
[2024-03-17T10:20:17.888+0000] {python.py:202} INFO - Done. Returned value was: None
[2024-03-17T10:20:17.895+0000] {taskinstance.py:1149} INFO - Marking task as SUCCESS. dag_id=my_dag, task_id=Options_Crawler, execution_date=20240317T101944, start_date=20240317T101945, end_date=20240317T102017
[2024-03-17T10:20:17.930+0000] {local_task_job_runner.py:234} INFO - Task exited with return code 0
[2024-03-17T10:20:17.942+0000] {taskinstance.py:3312} INFO - 0 downstream tasks scheduled from follow-on schedule check
